Cannot find a commit with reference '12345'. Possible reasons:

- the referenced commit does not exist
- the current working directory is not a git repository
- the git binary is not available

Try running `git show 12345` to debug the issue.
Traceback (most recent call last):
  File "/home/runner/work/semgrep/semgrep/semgrep/semgrep/git.py", line 68, in __init__
    subprocess.run(
  File "/usr/lib/python3.8/subprocess.py", line 516, in run
    raise CalledProcessError(retcode, process.args,
subprocess.CalledProcessError: Command '['git', 'cat-file', '-e', '12345']' returned non-zero exit status 128.

During handling of the above exception, another exception occurred:

Traceback (most recent call last):
  File "/home/runner/work/semgrep/semgrep/semgrep/semgrep/semgrep_main.py", line 310, in main
    baseline_handler = BaselineHandler(baseline_commit)
  File "/home/runner/work/semgrep/semgrep/semgrep/semgrep/git.py", line 75, in __init__
    raise Exception(
Exception: Cannot find a commit with reference '12345'. Possible reasons:

- the referenced commit does not exist
- the current working directory is not a git repository
- the git binary is not available

Try running `git show 12345` to debug the issue.

During handling of the above exception, another exception occurred:

Traceback (most recent call last):
  File "/home/runner/work/semgrep/semgrep/semgrep/semgrep/commands/scan.py", line 868, in scan
    ) = semgrep.semgrep_main.main(
  File "/home/runner/work/semgrep/semgrep/semgrep/semgrep/semgrep_main.py", line 313, in main
    raise SemgrepError(e)
semgrep.error.SemgrepError: Cannot find a commit with reference '12345'. Possible reasons:

- the referenced commit does not exist
- the current working directory is not a git repository
- the git binary is not available

Try running `git show 12345` to debug the issue.

During handling of the above exception, another exception occurred:

Traceback (most recent call last):
  File "/usr/lib/python3.8/runpy.py", line 194, in _run_module_as_main
    return _run_code(code, main_globals, None,
  File "/usr/lib/python3.8/runpy.py", line 87, in _run_code
    exec(code, run_globals)
  File "/home/runner/work/semgrep/semgrep/semgrep/semgrep/__main__.py", line 34, in <module>
    sys.exit(main())
  File "/home/runner/work/semgrep/semgrep/semgrep/semgrep/__main__.py", line 20, in main
    cli()
  File "/home/runner/.local/share/virtualenvs/semgrep-GqZ0EjEI/lib/python3.8/site-packages/click/core.py", line 1128, in __call__
    return self.main(*args, **kwargs)
  File "/home/runner/.local/share/virtualenvs/semgrep-GqZ0EjEI/lib/python3.8/site-packages/click/core.py", line 1053, in main
    rv = self.invoke(ctx)
  File "/home/runner/.local/share/virtualenvs/semgrep-GqZ0EjEI/lib/python3.8/site-packages/click/core.py", line 1659, in invoke
    return _process_result(sub_ctx.command.invoke(sub_ctx))
  File "/home/runner/.local/share/virtualenvs/semgrep-GqZ0EjEI/lib/python3.8/site-packages/click/core.py", line 1395, in invoke
    return ctx.invoke(self.callback, **ctx.params)
  File "/home/runner/.local/share/virtualenvs/semgrep-GqZ0EjEI/lib/python3.8/site-packages/click/core.py", line 754, in invoke
    return __callback(*args, **kwargs)
  File "/home/runner/work/semgrep/semgrep/semgrep/semgrep/commands/scan.py", line 897, in scan
    output_handler.output({}, all_targets=set(), filtered_rules=[])
  File "/home/runner/work/semgrep/semgrep/semgrep/semgrep/output.py", line 302, in output
    final_error = semgrep_core_errors[-1]
IndexError: list index out of range
